<robot name="BHR8FC2">
  <mujoco>
    <compiler meshdir="meshes" balanceinertia="true" discardvisual="true" />
  </mujoco>
  <link name="torso_link">
    <inertial>
      <origin xyz="-0.013598 0.001904 0.230955" rpy="0 0 0" />
      <mass value="22.473048" />
      <inertia ixx="0.640733" ixy="0.001978" ixz="-0.036086" iyy="0.531463" iyz="0.004586" izz="0.240139" />
    </inertial>
    <visual>
      <origin xyz="0 0 0" rpy="0 0 0" />
      <geometry>
        <mesh filename="meshes/torso_link.stl" />
      </geometry>
      <material name="">
        <color rgba="0.752941176470588 0.752941176470588 0.752941176470588 1" />
      </material>
    </visual>
    <collision>
      <origin xyz="0 0 0" rpy="0 0 0" />
      <geometry>
        <mesh filename="meshes/torso_link.stl" />
      </geometry>
    </collision>
  </link>
  <link name="right_hip_yaw_link">
    <inertial>
      <origin xyz="-0.078509 -0.000004 -0.118031" rpy="0 0 0" />
      <mass value="2.389579" />
      <inertia ixx="0.006148" ixy="0.000001" ixz="0.003865" iyy="0.011987" iyz="0.000000" izz="0.008234" />
    </inertial>
    <visual>
      <origin xyz="0 0 0" rpy="0 0 0" />
      <geometry>
        <mesh filename="meshes/right_hip_yaw_link.stl" />
      </geometry>
      <material name="">
        <color rgba="0.752941176470588 0.752941176470588 0.752941176470588 1" />
      </material>
    </visual>
    <collision>
      <origin xyz="0 0 0" rpy="0 0 0" />
      <geometry>
        <mesh filename="meshes/right_hip_yaw_link.stl" />
      </geometry>
    </collision>
  </link>
  <joint name="right_hip_yaw_joint" type="continuous">
    <origin xyz="0 -0.1 0.02324" rpy="0 0 0" />
    <parent link="torso_link" />
    <child link="right_hip_yaw_link" />
    <axis xyz="0 0 1" />
  </joint>
  <link name="right_hip_roll_link">
    <inertial>
      <origin xyz="0.051206 -0.002730 -0.000288" rpy="0 0 0" />
      <mass value="2.507088" />
      <inertia ixx="0.003451" ixy="-0.000024" ixz="0.000023" iyy="0.003613" iyz="0.000002" izz="0.004041" />
    </inertial>
    <visual>
      <origin xyz="0 0 0" rpy="0 0 0" />
      <geometry>
        <mesh filename="meshes/right_hip_roll_link.stl" />
      </geometry>
      <material name="">
        <color rgba="0.752941176470588 0.752941176470588 0.752941176470588 1" />
      </material>
    </visual>
    <collision>
      <origin xyz="0 0 0" rpy="0 0 0" />
      <geometry>
        <mesh filename="meshes/right_hip_roll_link.stl" />
      </geometry>
    </collision>
  </link>
  <joint name="right_hip_roll_joint" type="continuous">
    <origin xyz="-0.054 0 -0.13924" rpy="0 0 0" />
    <parent link="right_hip_yaw_link" />
    <child link="right_hip_roll_link" />
    <axis xyz="-1 0 0" />
  </joint>
  <link name="right_hip_pitch_link">
    <inertial>
      <origin xyz="0.005701 -0.002335 -0.170006" rpy="0 0 0" />
      <mass value="3.096463" />
      <inertia ixx="0.043059" ixy="0.000136" ixz="0.000276" iyy="0.040946" iyz="-0.000548" izz="0.005837" />
    </inertial>
    <visual>
      <origin xyz="0 0 0" rpy="0 0 0" />
      <geometry>
        <mesh filename="meshes/right_hip_pitch_link.stl" />
      </geometry>
      <material name="">
        <color rgba="0.752941176470588 0.752941176470588 0.752941176470588 1" />
      </material>
    </visual>
    <collision>
      <origin xyz="0 0 0" rpy="0 0 0" />
      <geometry>
        <mesh filename="meshes/right_hip_pitch_link.stl" />
      </geometry>
    </collision>
  </link>
  <joint name="right_hip_pitch_joint" type="continuous">
    <origin xyz="0.0550000000000002 -9.99999986171368E-05 0" rpy="0 0 0" />
    <parent link="right_hip_roll_link" />
    <child link="right_hip_pitch_link" />
    <axis xyz="0 1 0" />
  </joint>
  <link name="right_knee_link">
    <inertial>
      <origin xyz="0.003761 0.000004 -0.143175" rpy="0 0 0" />
      <mass value="1.914266" />
      <inertia ixx="0.017616" ixy="0.000003" ixz="0.000476" iyy="0.017018" iyz="-0.000020" izz="0.002115" />
    </inertial>
    <visual>
      <origin xyz="0 0 0" rpy="0 0 0" />
      <geometry>
        <mesh filename="meshes/right_knee_link.stl" />
      </geometry>
      <material name="">
        <color rgba="0.752941176470588 0.752941176470588 0.752941176470588 1" />
      </material>
    </visual>
    <collision>
      <origin xyz="0 0 0" rpy="0 0 0" />
      <geometry>
        <mesh filename="meshes/right_knee_link.stl" />
      </geometry>
    </collision>
  </link>
  <joint name="right_knee_joint" type="continuous">
    <origin xyz="0 0 -0.375" rpy="0 0 0" />
    <parent link="right_hip_pitch_link" />
    <child link="right_knee_link" />
    <axis xyz="0 1 0" />
  </joint>
  <link name="right_ankle_pitch_link">
    <inertial>
      <origin xyz="-0.025376 0.000103 0.003416" rpy="0 0 0" />
      <mass value="0.168311" />
      <inertia ixx="0.000045" ixy="0.000000" ixz="-0.000004" iyy="0.000173" iyz="0.000000" izz="0.000168" />
    </inertial>
    <visual>
      <origin xyz="0 0 0" rpy="0 0 0" />
      <geometry>
        <mesh filename="meshes/right_ankle_pitch_link.stl" />
      </geometry>
      <material name="">
        <color rgba="0.752941176470588 0.752941176470588 0.752941176470588 1" />
      </material>
    </visual>
    <collision>
      <origin xyz="0 0 0" rpy="0 0 0" />
      <geometry>
        <mesh filename="meshes/right_ankle_pitch_link.stl" />
      </geometry>
    </collision>
  </link>
  <joint name="right_ankle_pitch_joint" type="continuous">
    <origin xyz="0 0 -0.349999999999999" rpy="0 0 0" />
    <parent link="right_knee_link" />
    <child link="right_ankle_pitch_link" />
    <axis xyz="0 1 0" />
  </joint>
  <link name="right_ankle_roll_link">
    <inertial>
      <origin xyz="-0.061233 0.000106 -0.037793" rpy="0 0 0" />
      <mass value="1.581376" />
      <inertia ixx="0.002200" ixy="0.000031" ixz="-0.002098" iyy="0.009392" iyz="-0.000003" izz="0.008767" />
    </inertial>
    <visual>
      <origin xyz="0 0 0" rpy="0 0 0" />
      <geometry>
        <mesh filename="meshes/right_ankle_roll_link.stl" />
      </geometry>
      <material name="">
        <color rgba="0.752941176470588 0.752941176470588 0.752941176470588 1" />
      </material>
    </visual>
    <collision>
      <origin xyz="0 0 0" rpy="0 0 0" />
      <geometry>
        <mesh filename="meshes/right_ankle_roll_link.stl" />
      </geometry>
    </collision>
  </link>
  <joint name="right_ankle_roll_joint" type="continuous">
    <origin xyz="0.0410000000000016 0 0" rpy="0 0 0" />
    <parent link="right_ankle_pitch_link" />
    <child link="right_ankle_roll_link" />
    <axis xyz="1 0 0" />
  </joint>
  <link name="left_hip_yaw_link">
    <inertial>
      <origin xyz="-0.078509 -0.000004 -0.118031" rpy="0 0 0" />
      <mass value="2.389579" />
      <inertia ixx="0.006148" ixy="0.000001" ixz="0.003865" iyy="0.011987" iyz="0.000000" izz="0.008234" />
    </inertial>
    <visual>
      <origin xyz="0 0 0" rpy="0 0 0" />
      <geometry>
        <mesh filename="meshes/left_hip_yaw_link.stl" />
      </geometry>
      <material name="">
        <color rgba="0.752941176470588 0.752941176470588 0.752941176470588 1" />
      </material>
    </visual>
    <collision>
      <origin xyz="0 0 0" rpy="0 0 0" />
      <geometry>
        <mesh filename="meshes/left_hip_yaw_link.stl" />
      </geometry>
    </collision>
  </link>
  <joint name="left_hip_yaw_joint" type="continuous">
    <origin xyz="0 0.0999999999999999 0.02324" rpy="0 0 0" />
    <parent link="torso_link" />
    <child link="left_hip_yaw_link" />
    <axis xyz="0 0 1" />
  </joint>
  <link name="left_hip_roll_link">
    <inertial>
      <origin xyz="0.051206 0.002733 -0.000280" rpy="0 0 0" />
      <mass value="2.507222" />
      <inertia ixx="0.003451" ixy="0.000024" ixz="0.000023" iyy="0.003613" iyz="-0.000003" izz="0.004041" />
    </inertial>
    <visual>
      <origin xyz="0 0 0" rpy="0 0 0" />
      <geometry>
        <mesh filename="meshes/left_hip_roll_link.stl" />
      </geometry>
      <material name="">
        <color rgba="0.752941176470588 0.752941176470588 0.752941176470588 1" />
      </material>
    </visual>
    <collision>
      <origin xyz="0 0 0" rpy="0 0 0" />
      <geometry>
        <mesh filename="meshes/left_hip_roll_link.stl" />
      </geometry>
    </collision>
  </link>
  <joint name="left_hip_roll_joint" type="continuous">
    <origin xyz="-0.054 0 -0.13924" rpy="0 0 0" />
    <parent link="left_hip_yaw_link" />
    <child link="left_hip_roll_link" />
    <axis xyz="-1 0 0" />
  </joint>
  <link name="left_hip_pitch_link">
    <inertial>
      <origin xyz="0.004804 0.002343 -0.169952" rpy="0 0 0" />
      <mass value="3.096463" />
      <inertia ixx="0.043050" ixy="-0.000129" ixz="0.000379" iyy="0.040839" iyz="0.000543" izz="0.005739" />
    </inertial>
    <visual>
      <origin xyz="0 0 0" rpy="0 0 0" />
      <geometry>
        <mesh filename="meshes/left_hip_pitch_link.stl" />
      </geometry>
      <material name="">
        <color rgba="0.752941176470588 0.752941176470588 0.752941176470588 1" />
      </material>
    </visual>
    <collision>
      <origin xyz="0 0 0" rpy="0 0 0" />
      <geometry>
        <mesh filename="meshes/left_hip_pitch_link.stl" />
      </geometry>
    </collision>
  </link>
  <joint name="left_hip_pitch_joint" type="continuous">
    <origin xyz="0.0550000000000005 0.000100000001382744 0" rpy="0 0 0" />
    <parent link="left_hip_roll_link" />
    <child link="left_hip_pitch_link" />
    <axis xyz="0 -1 0" />
  </joint>
  <link name="left_knee_link">
    <inertial>
      <origin xyz="0.003757 -0.000290 -0.143175" rpy="0 0 0" />
      <mass value="1.914266" />
      <inertia ixx="0.017616" ixy="0.000000" ixz="0.000476" iyy="0.017019" iyz="0.000022" izz="0.002115" />
    </inertial>
    <visual>
      <origin xyz="0 0 0" rpy="0 0 0" />
      <geometry>
        <mesh filename="meshes/left_knee_link.stl" />
      </geometry>
      <material name="">
        <color rgba="0.752941176470588 0.752941176470588 0.752941176470588 1" />
      </material>
    </visual>
    <collision>
      <origin xyz="0 0 0" rpy="0 0 0" />
      <geometry>
        <mesh filename="meshes/left_knee_link.stl" />
      </geometry>
    </collision>
  </link>
  <joint name="left_knee_joint" type="continuous">
    <origin xyz="0 0 -0.375" rpy="0 0 0" />
    <parent link="left_hip_pitch_link" />
    <child link="left_knee_link" />
    <axis xyz="0 -1 0" />
  </joint>
  <link name="left_ankle_pitch_link">
    <inertial>
      <origin xyz="-0.025376 0.000103 0.003416" rpy="0 0 0" />
      <mass value="0.168311" />
      <inertia ixx="0.000045" ixy="0.000000" ixz="-0.000004" iyy="0.000173" iyz="0.000000" izz="0.000168" />
    </inertial>
    <visual>
      <origin xyz="0 0 0" rpy="0 0 0" />
      <geometry>
        <mesh filename="meshes/left_ankle_pitch_link.stl" />
      </geometry>
      <material name="">
        <color rgba="0.752941176470588 0.752941176470588 0.752941176470588 1" />
      </material>
    </visual>
    <collision>
      <origin xyz="0 0 0" rpy="0 0 0" />
      <geometry>
        <mesh filename="meshes/left_ankle_pitch_link.stl" />
      </geometry>
    </collision>
  </link>
  <joint name="left_ankle_pitch_joint" type="continuous">
    <origin xyz="0 0 -0.35" rpy="0 0 0" />
    <parent link="left_knee_link" />
    <child link="left_ankle_pitch_link" />
    <axis xyz="0 -1 0" />
  </joint>
  <link name="left_ankle_roll_link">
    <inertial>
      <origin xyz="-0.061228 -0.000129 -0.037791" rpy="0 0 0" />
      <mass value="1.581270" />
      <inertia ixx="0.002200" ixy="-0.000030" ixz="-0.002098" iyy="0.009391" iyz="0.000001" izz="0.008766" />
    </inertial>
    <visual>
      <origin xyz="0 0 0" rpy="0 0 0" />
      <geometry>
        <mesh filename="meshes/left_ankle_roll_link.stl" />
      </geometry>
      <material name="">
        <color rgba="0.752941176470588 0.752941176470588 0.752941176470588 1" />
      </material>
    </visual>
    <collision>
      <origin xyz="0 0 0" rpy="0 0 0" />
      <geometry>
        <mesh filename="meshes/left_ankle_roll_link.stl" />
      </geometry>
    </collision>
  </link>
  <joint name="left_ankle_roll_joint" type="continuous">
    <origin xyz="0.0410000000000001 0 0" rpy="0 0 0" />
    <parent link="left_ankle_pitch_link" />
    <child link="left_ankle_roll_link" />
    <axis xyz="-1 0 0" />
  </joint>
  <link name="right_shoulder_pitch_link">
    <inertial>
      <origin xyz="-0.072957 -0.077869 0.000004" rpy="0 0 0" />
      <mass value="1.938195" />
      <inertia ixx="0.002538" ixy="0.000898" ixz="-0.000001" iyy="0.006956" iyz="0.000000" izz="0.007542" />
    </inertial>
    <visual>
      <origin xyz="0 0 0" rpy="0 0 0" />
      <geometry>
        <mesh filename="meshes/right_shoulder_pitch_link.stl" />
      </geometry>
      <material name="">
        <color rgba="0.752941176470588 0.752941176470588 0.752941176470588 1" />
      </material>
    </visual>
    <collision>
      <origin xyz="0 0 0" rpy="0 0 0" />
      <geometry>
        <mesh filename="meshes/right_shoulder_pitch_link.stl" />
      </geometry>
    </collision>
  </link>
  <joint name="right_shoulder_pitch_joint" type="continuous">
    <origin xyz="-0.0262500000000002 -0.13476 0.389" rpy="0 0 0" />
    <parent link="torso_link" />
    <child link="right_shoulder_pitch_link" />
    <axis xyz="0 -1 0" />
  </joint>
  <link name="right_shoulder_roll_link">
    <inertial>
      <origin xyz="0.050911 0.000002 -0.017501" rpy="0 0 0" />
      <mass value="2.116461" />
      <inertia ixx="0.002659" ixy="0.000000" ixz="0.000079" iyy="0.003457" iyz="0.000000" izz="0.003122" />
    </inertial>
    <visual>
      <origin xyz="0 0 0" rpy="0 0 0" />
      <geometry>
        <mesh filename="meshes/right_shoulder_roll_link.stl" />
      </geometry>
      <material name="">
        <color rgba="0.752941176470588 0.752941176470588 0.752941176470588 1" />
      </material>
    </visual>
    <collision>
      <origin xyz="0 0 0" rpy="0 0 0" />
      <geometry>
        <mesh filename="meshes/right_shoulder_roll_link.stl" />
      </geometry>
    </collision>
  </link>
  <joint name="right_shoulder_roll_joint" type="continuous">
    <origin xyz="-0.049 -0.0842399999999996 0" rpy="0 0 0" />
    <parent link="right_shoulder_pitch_link" />
    <child link="right_shoulder_roll_link" />
    <axis xyz="1 0 0" />
  </joint>
  <link name="right_shoulder_yaw_link">
    <inertial>
      <origin xyz="0.002752 0.000004 -0.123717" rpy="0 0 0" />
      <mass value="1.703058" />
      <inertia ixx="0.012105" ixy="0.000000" ixz="-0.000652" iyy="0.011971" iyz="0.000000" izz="0.001265" />
    </inertial>
    <visual>
      <origin xyz="0 0 0" rpy="0 0 0" />
      <geometry>
        <mesh filename="meshes/right_shoulder_yaw_link.stl" />
      </geometry>
      <material name="">
        <color rgba="0.752941176470588 0.752941176470588 0.752941176470588 1" />
      </material>
    </visual>
    <collision>
      <origin xyz="0 0 0" rpy="0 0 0" />
      <geometry>
        <mesh filename="meshes/right_shoulder_yaw_link.stl" />
      </geometry>
    </collision>
  </link>
  <joint name="right_shoulder_yaw_joint" type="continuous">
    <origin xyz="0.049 0 -0.0497599999999999" rpy="0 0 0" />
    <parent link="right_shoulder_roll_link" />
    <child link="right_shoulder_yaw_link" />
    <axis xyz="0 0 1" />
  </joint>
  <link name="right_elbow_link">
    <inertial>
      <origin xyz="0.002409 0.009994 -0.089886" rpy="0 0 0" />
      <mass value="0.181283" />
      <inertia ixx="0.001368" ixy="0.000000" ixz="0.000029" iyy="0.001374" iyz="0.000000" izz="0.000040" />
    </inertial>
    <visual>
      <origin xyz="0 0 0" rpy="0 0 0" />
      <geometry>
        <mesh filename="meshes/right_elbow_link.stl" />
      </geometry>
      <material name="">
        <color rgba="0.752941176470588 0.752941176470588 0.752941176470588 1" />
      </material>
    </visual>
    <collision>
      <origin xyz="0 0 0" rpy="0 0 0" />
      <geometry>
        <mesh filename="meshes/right_elbow_link.stl" />
      </geometry>
    </collision>
  </link>
  <joint name="right_elbow_joint" type="continuous">
    <origin xyz="0 -0.0100000000000002 -0.30324" rpy="0 0 0" />
    <parent link="right_shoulder_yaw_link" />
    <child link="right_elbow_link" />
    <axis xyz="0 -1 0" />
  </joint>
  <link name="left_shoulder_pitch_link">
    <inertial>
      <origin xyz="-0.072957 0.077869 -0.000004" rpy="0 0 0" />
      <mass value="1.938195" />
      <inertia ixx="0.002538" ixy="-0.000898" ixz="0.000001" iyy="0.006956" iyz="0.000000" izz="0.007542" />
    </inertial>
    <visual>
      <origin xyz="0 0 0" rpy="0 0 0" />
      <geometry>
        <mesh filename="meshes/left_shoulder_pitch_link.stl" />
      </geometry>
      <material name="">
        <color rgba="0.752941176470588 0.752941176470588 0.752941176470588 1" />
      </material>
    </visual>
    <collision>
      <origin xyz="0 0 0" rpy="0 0 0" />
      <geometry>
        <mesh filename="meshes/left_shoulder_pitch_link.stl" />
      </geometry>
    </collision>
  </link>
  <joint name="left_shoulder_pitch_joint" type="continuous">
    <origin xyz="-0.0262500000000013 0.13476 0.389" rpy="0 0 0" />
    <parent link="torso_link" />
    <child link="left_shoulder_pitch_link" />
    <axis xyz="0 1 0" />
  </joint>
  <link name="left_shoulder_roll_link">
    <inertial>
      <origin xyz="0.050911 0.000002 -0.017501" rpy="0 0 0" />
      <mass value="2.116461" />
      <inertia ixx="0.002659" ixy="0.000000" ixz="0.000079" iyy="0.003457" iyz="0.000000" izz="0.003122" />
    </inertial>
    <visual>
      <origin xyz="0 0 0" rpy="0 0 0" />
      <geometry>
        <mesh filename="meshes/left_shoulder_roll_link.stl" />
      </geometry>
      <material name="">
        <color rgba="0.752941176470588 0.752941176470588 0.752941176470588 1" />
      </material>
    </visual>
    <collision>
      <origin xyz="0 0 0" rpy="0 0 0" />
      <geometry>
        <mesh filename="meshes/left_shoulder_roll_link.stl" />
      </geometry>
    </collision>
  </link>
  <joint name="left_shoulder_roll_joint" type="continuous">
    <origin xyz="-0.049 0.0842399999999999 0" rpy="0 0 0" />
    <parent link="left_shoulder_pitch_link" />
    <child link="left_shoulder_roll_link" />
    <axis xyz="1 0 0" />
  </joint>
  <link name="left_shoulder_yaw_link">
    <inertial>
      <origin xyz="0.002752 0.000004 -0.123717" rpy="0 0 0" />
      <mass value="1.703058" />
      <inertia ixx="0.012105" ixy="0.000000" ixz="-0.000652" iyy="0.011971" iyz="0.000000" izz="0.001265" />
    </inertial>
    <visual>
      <origin xyz="0 0 0" rpy="0 0 0" />
      <geometry>
        <mesh filename="meshes/left_shoulder_yaw_link.stl" />
      </geometry>
      <material name="">
        <color rgba="0.752941176470588 0.752941176470588 0.752941176470588 1" />
      </material>
    </visual>
    <collision>
      <origin xyz="0 0 0" rpy="0 0 0" />
      <geometry>
        <mesh filename="meshes/left_shoulder_yaw_link.stl" />
      </geometry>
    </collision>
  </link>
  <joint name="left_shoulder_yaw_joint" type="continuous">
    <origin xyz="0.049 0 -0.04976" rpy="0 0 0" />
    <parent link="left_shoulder_roll_link" />
    <child link="left_shoulder_yaw_link" />
    <axis xyz="0 0 1" />
  </joint>
  <link name="left_elbow_link">
    <inertial>
      <origin xyz="0.002409 -0.010006 -0.089886" rpy="0 0 0" />
      <mass value="0.181283" />
      <inertia ixx="0.001368" ixy="0.000000" ixz="0.000029" iyy="0.001374" iyz="0.000000" izz="0.000040" />
    </inertial>
    <visual>
      <origin xyz="0 0 0" rpy="0 0 0" />
      <geometry>
        <mesh filename="meshes/left_elbow_link.stl" />
      </geometry>
      <material name="">
        <color rgba="0.752941176470588 0.752941176470588 0.752941176470588 1" />
      </material>
    </visual>
    <collision>
      <origin xyz="0 0 0" rpy="0 0 0" />
      <geometry>
        <mesh filename="meshes/left_elbow_link.stl" />
      </geometry>
    </collision>
  </link>
  <joint name="left_elbow_joint" type="continuous">
    <origin xyz="0 0.0099999999999949 -0.30324" rpy="0 0 0" />
    <parent link="left_shoulder_yaw_link" />
    <child link="left_elbow_link" />
    <axis xyz="0 1 0" />
  </joint>
  <link name="head_link">
    <inertial>
      <origin xyz="-0.020501 0.001926 0.089361" rpy="0 0 0" />
      <mass value="0.618693" />
      <inertia ixx="0.001909" ixy="-0.000068" ixz="-0.000359" iyy="0.002331" iyz="0.000041" izz="0.002378" />
    </inertial>
    <visual>
      <origin xyz="0 0 0" rpy="0 0 0" />
      <geometry>
        <mesh filename="meshes/head_link.stl" />
      </geometry>
      <material name="">
        <color rgba="0.752941176470588 0.752941176470588 0.752941176470588 1" />
      </material>
    </visual>
    <collision>
      <origin xyz="0 0 0" rpy="0 0 0" />
      <geometry>
        <mesh filename="meshes/head_link.stl" />
      </geometry>
    </collision>
  </link>
  <joint name="head_link_joint" type="fixed">
    <origin xyz="0.03 0 0.493594020755785" rpy="0 0 0" />
    <parent link="torso_link" />
    <child link="head_link" />
    <axis xyz="0 0 0" />
  </joint>
</robot>